Workbook
Name \a: #REF!
Name \a: #REF!
Name \b: #REF!
Name \b: #REF!
Name \m: #REF!
Name \m: #REF!
Name \p: #REF!
Name \p: #REF!
Name \r: #REF!
Name \r: #REF!
Name ____________________MES1: #REF!
Name ____________________MES1: #REF!
Name ____________________MES2: #REF!
Name ____________________MES2: #REF!
Name ____________________MES3: #REF!
Name ____________________MES3: #REF!
Name ___________________MES1: #REF!
Name ___________________MES1: #REF!
Name ___________________MES2: #REF!
Name ___________________MES2: #REF!
Name ___________________MES3: #REF!
Name ___________________MES3: #REF!
Name __________________MES1: #REF!
Name __________________MES1: #REF!
Name __________________MES2: #REF!
Name __________________MES2: #REF!
Name __________________MES3: #REF!
Name __________________MES3: #REF!
Name _________________MES1: #REF!
Name _________________MES1: #REF!
Name _________________MES2: #REF!
Name _________________MES2: #REF!
Name _________________MES3: #REF!
Name _________________MES3: #REF!
Name ________________MES1: #REF!
Name ________________MES1: #REF!
Name ________________MES2: #REF!
Name ________________MES2: #REF!
Name ________________MES3: #REF!
Name ________________MES3: #REF!
Name _______________MES1: #REF!
Name _______________MES1: #REF!
Name _______________MES1: #REF!
Name _______________MES2: #REF!
Name _______________MES2: #REF!
Name _______________MES2: #REF!
Name _______________MES3: #REF!
Name _______________MES3: #REF!
Name _______________MES3: #REF!
Name ______________MES1: #REF!
Name ______________MES1: #REF!
Name ______________MES2: #REF!
Name ______________MES2: #REF!
Name ______________MES3: #REF!
Name ______________MES3: #REF!
Name _____________MES1: #REF!
Name _____________MES1: #REF!
Name _____________MES2: #REF!
Name _____________MES2: #REF!
Name _____________MES3: #REF!

Sheet For Brendan
C3: Upper Nass CU | X3: Lower Nass and Coastal CU | AH3: Aggregate (combined CU's)
E4: Upper escapement | H4: Middle escapement | K4: GW Run size | N4: Harvest | AA4: Harvest | AK4: Harvest
B5: Year | C5: Net escapement | E5: Estimate | F5: SD | H5: Estimate | I5: SD | K5: Estimate | L5: SD | N5: In River | O5: Marine | P5: Alaska | Q5: Total | S5: Total Run | T5: Harvest Rate | U5: Upper harvest | V5: Middle harvest | X5: Year | Y5: Net escapement | AA5: In River | AB5: Marine | AC5: Alaska | AD5: Total | AF5: Total Run | AH5: Year | AI5: Net escapement | AK5: In River | AL5: Marine | AM5: Alaska | AN5: Total | AP5: Total Run
B6: 1992 | C6: ='A6-Chin (NEW2)'!C13 -> 16808 | K6: ='A6-Chin (NEW2)'!L13 -> 20067.173 | N6: ='A6a-Chin (Upper&MidCU)'!AA13 -> 8791.1748 | O6: ='A6a-Chin (Upper&MidCU)'!AE13 -> 7727.6303 | P6: ='A6a-Chin (Upper&MidCU)'!AK13 -> 1550.3811 | Q6: =SUM(N6:P6) -> 18069.186 | S6: ='A6a-Chin (Upper&MidCU)'!AL13 -> 34877.186 | T6: =Q6/S6 -> 0.51808039 | X6: 1992 | Y6: ='A6b-Chin (LN&CoastalCU)'!P13 -> 2053.3284 | AA6: ='A6b-Chin (LN&CoastalCU)'!AA13 -> 218.8252 | AB6: ='A6b-Chin (LN&CoastalCU)'!AE13 -> 944.03635 | AC6: ='A6b-Chin (LN&CoastalCU)'!AL13 -> 149.61891 | AD6: =SUM(AA6:AC6) -> 1312.4805 | AF6: ='A6b-Chin (LN&CoastalCU)'!AM13 -> 3365.8969 | AH6: 1992 | AI6: =SUM(C6,Y6) -> 18861.328 | AK6: =SUM(N6,AA6) -> 9010 | AL6: =SUM(O6,AB6) -> 8671.6667 | AM6: =SUM(P6,AC6) -> 1700 | AN6: =SUM(Q6,AD6) -> 19381.667 | AP6: =SUM(S6,AF6) -> 38243.083
B7: 1993 | C7: ='A6-Chin (NEW2)'!C14 -> 24814 | K7: ='A6-Chin (NEW2)'!L14 -> 27923.118 | N7: ='A6a-Chin (Upper&MidCU)'!AA14 -> 6924.6051 | O7: ='A6a-Chin (Upper&MidCU)'!AE14 -> 11344.254 | P7: ='A6a-Chin (Upper&MidCU)'!AK14 -> 2030.9507 | Q7: =SUM(N7:P7) -> 20299.81 | S7: ='A6a-Chin (Upper&MidCU)'!AL14 -> 45113.81 | T7: =Q7/S7 -> 0.44996886 | X7: 1993 | Y7: ='A6b-Chin (LN&CoastalCU)'!P14 -> 2293.2596 | AA7: ='A6b-Chin (LN&CoastalCU)'!AA14 -> 244.3949 | AB7: ='A6b-Chin (LN&CoastalCU)'!AE14 -> 1048.4129 | AC7: ='A6b-Chin (LN&CoastalCU)'!AL14 -> 169.04928 | AD7: =SUM(AA7:AC7) -> 1461.8571 | AF7: ='A6b-Chin (LN&CoastalCU)'!AM14 -> 3755.1936 | AH7: 1993 | AI7: =SUM(C7,Y7) -> 27107.26 | AK7: =SUM(N7,AA7) -> 7169 | AL7: =SUM(O7,AB7) -> 12392.667 | AM7: =SUM(P7,AC7) -> 2200 | AN7: =SUM(Q7,AD7) -> 21761.667 | AP7: =SUM(S7,AF7) -> 48869.003
B8: 1994 | C8: ='A6-Chin (NEW2)'!C15 -> 23639.335 | E8: ='A6-Chin (NEW2)'!D15 -> 19706.335 | F8: ='Bayesian SD Ests (10Feb26rev)'!D10 -> 3851 | H8: ='Bayesian SD Ests (10Feb26rev)'!F10 -> 3933 | I8: ='Bayesian SD Ests (10Feb26rev)'!G10 -> 1470 | K8: ='A6-Chin (NEW2)'!L15 -> 26750 | L8: ='Bayesian SD Ests (10Feb26rev)'!V10 -> 4080 | N8: ='A6a-Chin (Upper&MidCU)'!AA15 -> 6610.2704 | O8: ='A6a-Chin (Upper&MidCU)'!AE15 -> 8584.1557 | P8: ='A6a-Chin (Upper&MidCU)'!AK15 -> 1805.2605 | Q8: =SUM(N8:P8) -> 16999.687 | S8: ='A6a-Chin (Upper&MidCU)'!AL15 -> 40639.022 | T8: =Q8/S8 -> 0.41830944 | U8: =(E8/(1-T8))*T8 -> 14171.36 | V8: =(H8/(1-T8))*T8 -> 2828.3269 | X8: 1994 | Y8: ='A6b-Chin (LN&CoastalCU)'!P15 -> 5777.6481 | AA8: ='A6b-Chin (LN&CoastalCU)'!AA15 -> 615.72956 | AB8: ='A6b-Chin (LN&CoastalCU)'!AE15 -> 2098.0383 | AC8: ='A6b-Chin (LN&CoastalCU)'!AL15 -> 394.73947 | AD8: =SUM(AA8:AC8) -> 3108.5073 | AF8: ='A6b-Chin (LN&CoastalCU)'!AM15 -> 8886.3349 | AH8: 1994 | AI8: =SUM(C8,Y8) -> 29416.983 | AK8: =SUM(N8,AA8) -> 7226 | AL8: =SUM(O8,AB8) -> 10682.194 | AM8: =SUM(P8,AC8) -> 2200 | AN8: =SUM(Q8,AD8) -> 20108.194 | AP8: =SUM(S8,AF8) -> 49525.357
B9: 1995 | C9: ='A6-Chin (NEW2)'!C16 -> 9184.6097 | E9: ='A6-Chin (NEW2)'!D16 -> 7465.6097 | F9: ='Bayesian SD Ests (10Feb26rev)'!D11 -> 1951 | H9: ='Bayesian SD Ests (10Feb26rev)'!F11 -> 1719 | I9: ='Bayesian SD Ests (10Feb26rev)'!G11 -> 687 | K9: ='A6-Chin (NEW2)'!L16 -> 11764 | L9: ='Bayesian SD Ests (10Feb26rev)'!V11 -> 2133 | N9: ='A6a-Chin (Upper&MidCU)'!AA16 -> 7302.8426 | O9: ='A6a-Chin (Upper&MidCU)'!AE16 -> 4568.5056 | P9: ='A6a-Chin (Upper&MidCU)'!AK16 -> 974.50633 | Q9: =SUM(N9:P9) -> 12845.855 | S9: ='A6a-Chin (Upper&MidCU)'!AL16 -> 22030.464 | T9: =Q9/S9 -> 0.58309505 | U9: =(E9/(1-T9))*T9 -> 10441.613 | V9: =(H9/(1-T9))*T9 -> 2404.242 | X9: 1995 | Y9: ='A6b-Chin (LN&CoastalCU)'!P16 -> 1690.4926 | AA9: ='A6b-Chin (LN&CoastalCU)'!AA16 -> 180.15743 | AB9: ='A6b-Chin (LN&CoastalCU)'!AE16 -> 840.86588 | AC9: ='A6b-Chin (LN&CoastalCU)'!AL16 -> 125.49367 | AD9: =SUM(AA9:AC9) -> 1146.517 | AF9: ='A6b-Chin (LN&CoastalCU)'!AM16 -> 2837.1237 | AH9: 1995 | AI9: =SUM(C9,Y9) -> 10875.102 | AK9: =SUM(N9,AA9) -> 7483 | AL9: =SUM(O9,AB9) -> 5409.3715 | AM9: =SUM(P9,AC9) -> 1100 | AN9: =SUM(Q9,AD9) -> 13992.372 | AP9: =SUM(S9,AF9) -> 24867.588
B10: 1996 | C10: ='A6-Chin (NEW2)'!C17 -> 21721.665 | E10: ='A6-Chin (NEW2)'!D17 -> 18211.665 | F10: ='Bayesian SD Ests (10Feb26rev)'!D12 -> 4880 | H10: ='Bayesian SD Ests (10Feb26rev)'!F12 -> 3510 | I10: ='Bayesian SD Ests (10Feb26rev)'!G12 -> 1443 | K10: ='A6-Chin (NEW2)'!L17 -> 24082 | L10: ='Bayesian SD Ests (10Feb26rev)'!V12 -> 5437 | N10: ='A6a-Chin (Upper&MidCU)'!AA17 -> 7999.5787 | O10: ='A6a-Chin (Upper&MidCU)'!AE17 -> 9451.1184 | P10: ='A6a-Chin (Upper&MidCU)'!AK17 -> 1845.6719 | Q10: =SUM(N10:P10) -> 19296.369 | S10: ='A6a-Chin (Upper&MidCU)'!AL17 -> 41018.034 | T10: =Q10/S10 -> 0.47043622 | U10: =(E10/(1-T10))*T10 -> 16178.272 | V10: =(H10/(1-T10))*T10 -> 3118.0968 | X10: 1996 | Y10: ='A6b-Chin (LN&CoastalCU)'!P17 -> 2124.6061 | AA10: ='A6b-Chin (LN&CoastalCU)'!AA17 -> 226.42133 | AB10: ='A6b-Chin (LN&CoastalCU)'!AE17 -> 924.41826 | AC10: ='A6b-Chin (LN&CoastalCU)'!AL17 -> 154.32814 | AD10: =SUM(AA10:AC10) -> 1305.1677 | AF10: ='A6b-Chin (LN&CoastalCU)'!AM17 -> 3429.851 | AH10: 1996 | AI10: =SUM(C10,Y10) -> 23846.272 | AK10: =SUM(N10,AA10) -> 8226 | AL10: =SUM(O10,AB10) -> 10375.537 | AM10: =SUM(P10,AC10) -> 2000 | AN10: =SUM(Q10,AD10) -> 20601.537 | AP10: =SUM(S10,AF10) -> 44447.885
B11: 1997 | C11: ='A6-Chin (NEW2)'!C18 -> 21372.273 | E11: ='A6-Chin (NEW2)'!D18 -> 17879.273 | F11: ='Bayesian SD Ests (10Feb26rev)'!D13 -> 2187 | H11: ='Bayesian SD Ests (10Feb26rev)'!F13 -> 3493 | I11: ='Bayesian SD Ests (10Feb26rev)'!G13 -> 1520 | K11: ='A6-Chin (NEW2)'!L18 -> 23493 | L11: ='Bayesian SD Ests (10Feb26rev)'!V13 -> 2378 | N11: ='A6a-Chin (Upper&MidCU)'!AA18 -> 6629.614 | O11: ='A6a-Chin (Upper&MidCU)'!AE18 -> 7883.4226 | P11: ='A6a-Chin (Upper&MidCU)'!AK18 -> 1691.5659 | Q11: =SUM(N11:P11) -> 16204.603 | S11: ='A6a-Chin (Upper&MidCU)'!AL18 -> 37576.876 | T11: =Q11/S11 -> 0.43123869 | U11: =(E11/(1-T11))*T11 -> 13556.186 | V11: =(H11/(1-T11))*T11 -> 2648.4163 | X11: 1997 | Y11: ='A6b-Chin (LN&CoastalCU)'!P18 -> 2996.9324 | AA11: ='A6b-Chin (LN&CoastalCU)'!AA18 -> 319.38599 | AB11: ='A6b-Chin (LN&CoastalCU)'!AE18 -> 1105.4549 | AC11: ='A6b-Chin (LN&CoastalCU)'!AL18 -> 208.43407 | AD11: =SUM(AA11:AC11) -> 1633.275 | AF11: ='A6b-Chin (LN&CoastalCU)'!AM18 -> 4630.3171 | AH11: 1997 | AI11: =SUM(C11,Y11) -> 24369.206 | AK11: =SUM(N11,AA11) -> 6949 | AL11: =SUM(O11,AB11) -> 8988.8775 | AM11: =SUM(P11,AC11) -> 1900 | AN11: =SUM(Q11,AD11) -> 17837.878 | AP11: =SUM(S11,AF11) -> 42207.193
B12: 1998 | C12: ='A6-Chin (NEW2)'!C19 -> 24908 | E12: ='A6-Chin (NEW2)'!D19 -> 20875 | F12: ='Bayesian SD Ests (10Feb26rev)'!D14 -> 2806 | H12: ='Bayesian SD Ests (10Feb26rev)'!F14 -> 4033 | I12: ='Bayesian SD Ests (10Feb26rev)'!G14 -> 1800 | K12: ='A6-Chin (NEW2)'!L19 -> 27044 | L12: ='Bayesian SD Ests (10Feb26rev)'!V14 -> 3197 | N12: ='A6a-Chin (Upper&MidCU)'!AA19 -> 9307.1346 | O12: ='A6a-Chin (Upper&MidCU)'!AE19 -> 10257.187 | P12: ='A6a-Chin (Upper&MidCU)'!AK19 -> 2099.0245 | Q12: =SUM(N12:P12) -> 21663.346 | S12: ='A6a-Chin (Upper&MidCU)'!AL19 -> 46571.346 | T12: =Q12/S12 -> 0.4651647 | U12: =(E12/(1-T12))*T12 -> 18155.707 | V12: =(H12/(1-T12))*T12 -> 3507.6391 | X12: 1998 | Y12: ='A6b-Chin (LN&CoastalCU)'!P19 -> 2804.379 | AA12: ='A6b-Chin (LN&CoastalCU)'!AA19 -> 298.86539 | AB12: ='A6b-Chin (LN&CoastalCU)'!AE19 -> 1154.8515 | AC12: ='A6b-Chin (LN&CoastalCU)'!AL19 -> 200.97551 | AD12: =SUM(AA12:AC12) -> 1654.6924 | AF12: ='A6b-Chin (LN&CoastalCU)'!AM19 -> 4459.1588 | AH12: 1998 | AI12: =SUM(C12,Y12) -> 27712.379 | AK12: =SUM(N12,AA12) -> 9606 | AL12: =SUM(O12,AB12) -> 11412.038 | AM12: =SUM(P12,AC12) -> 2300 | AN12: =SUM(Q12,AD12) -> 23318.038 | AP12: =SUM(S12,AF12) -> 51030.505
B13: 1999 | C13: ='A6-Chin (NEW2)'!C20 -> 13069 | E13: ='A6-Chin (NEW2)'!D20 -> 10844 | F13: ='Bayesian SD Ests (10Feb26rev)'!D15 -> 1502 | H13: ='Bayesian SD Ests (10Feb26rev)'!F15 -> 2225 | I13: ='Bayesian SD Ests (10Feb26rev)'!G15 -> 985 | K13: ='A6-Chin (NEW2)'!L20 -> 14952 | L13: ='Bayesian SD Ests (10Feb26rev)'!V15 -> 1797 | N13: ='A6a-Chin (Upper&MidCU)'!AA20 -> 8983.1044 | O13: ='A6a-Chin (Upper&MidCU)'!AE20 -> 6295.1598 | P13: ='A6a-Chin (Upper&MidCU)'!AK20 -> 1351.5648 | Q13: =SUM(N13:P13) -> 16629.829 | S13: ='A6a-Chin (Upper&MidCU)'!AL20 -> 29698.829 | T13: =Q13/S13 -> 0.55994898 | U13: =(E13/(1-T13))*T13 -> 13798.597 | V13: =(H13/(1-T13))*T13 -> 2831.2319 | X13: 1999 | Y13: ='A6b-Chin (LN&CoastalCU)'!P20 -> 1960.1549 | AA13: ='A6b-Chin (LN&CoastalCU)'!AA20 -> 208.8956 | AB13: ='A6b-Chin (LN&CoastalCU)'!AE20 -> 944.17998 | AC13: ='A6b-Chin (LN&CoastalCU)'!AL20 -> 148.43523 | AD13: =SUM(AA13:AC13) -> 1301.5108 | AF13: ='A6b-Chin (LN&CoastalCU)'!AM20 -> 3261.7647 | AH13: 1999 | AI13: =SUM(C13,Y13) -> 15029.155 | AK13: =SUM(N13,AA13) -> 9192 | AL13: =SUM(O13,AB13) -> 7239.3398 | AM13: =SUM(P13,AC13) -> 1500 | AN13: =SUM(Q13,AD13) -> 17931.34 | AP13: =SUM(S13,AF13) -> 32960.594
B14: 2000 | C14: ='A6-Chin (NEW2)'!C21 -> 18085 | E14: ='A6-Chin (NEW2)'!D21 -> 14915 | F14: ='Bayesian SD Ests (10Feb26rev)'!D16 -> 3216 | H14: ='Bayesian SD Ests (10Feb26rev)'!F16 -> 3170 | I14: ='Bayesian SD Ests (10Feb26rev)'!G16 -> 1242 | K14: ='A6-Chin (NEW2)'!L21 -> 21655 | L14: ='Bayesian SD Ests (10Feb26rev)'!V16 -> 3498 | N14: ='A6a-Chin (Upper&MidCU)'!AA21 -> 10262.331 | O14: ='A6a-Chin (Upper&MidCU)'!AE21 -> 2456.1992 | P14: ='A6a-Chin (Upper&MidCU)'!AK21 -> 1444.0891 | Q14: =SUM(N14:P14) -> 14162.619 | S14: ='A6a-Chin (Upper&MidCU)'!AL21 -> 32247.619 | T14: =Q14/S14 -> 0.4391834 | U14: =(E14/(1-T14))*T14 -> 11680.147 | V14: =(H14/(1-T14))*T14 -> 2482.4718 | X14: 2000 | Y14: ='A6b-Chin (LN&CoastalCU)'!P21 -> 2619.7621 | AA14: ='A6b-Chin (LN&CoastalCU)'!AA21 -> 350.13643 | AB14: ='A6b-Chin (LN&CoastalCU)'!AE21 -> 355.80081 | AC14: ='A6b-Chin (LN&CoastalCU)'!AL21 -> 155.9109 | AD14: =SUM(AA14:AC14) -> 861.84814 | AF14: ='A6b-Chin (LN&CoastalCU)'!AM21 -> 3481.7077 | AH14: 2000 | AI14: =SUM(C14,Y14) -> 20704.762 | AK14: =SUM(N14,AA14) -> 10612.467 | AL14: =SUM(O14,AB14) -> 2812 | AM14: =SUM(P14,AC14) -> 1600 | AN14: =SUM(Q14,AD14) -> 15024.467 | AP14: =SUM(S14,AF14) -> 35729.327
B15: 2001 | C15: ='A6-Chin (NEW2)'!C22 -> 29341 | E15: ='A6-Chin (NEW2)'!D22 -> 24024 | F15: ='Bayesian SD Ests (10Feb26rev)'!D17 -> 2995 | H15: ='Bayesian SD Ests (10Feb26rev)'!F17 -> 5317 | I15: ='Bayesian SD Ests (10Feb26rev)'!G17 -> 2321 | K15: ='A6-Chin (NEW2)'!L22 -> 35715 | L15: ='Bayesian SD Ests (10Feb26rev)'!V17 -> 3313 | N15: ='A6a-Chin (Upper&MidCU)'!AA22 -> 12467.784 | O15: ='A6a-Chin (Upper&MidCU)'!AE22 -> 2253.9159 | P15: ='A6a-Chin (Upper&MidCU)'!AK22 -> 2030.22 | Q15: =SUM(N15:P15) -> 16751.92 | S15: ='A6a-Chin (Upper&MidCU)'!AL22 -> 46092.92 | T15: =Q15/S15 -> 0.36343803 | U15: =(E15/(1-T15))*T15 -> 13716.237 | V15: =(H15/(1-T15))*T15 -> 3035.6824 | X15: 2001 | Y15: ='A6b-Chin (LN&CoastalCU)'!P22 -> 4934.8372 | AA15: ='A6b-Chin (LN&CoastalCU)'!AA22 -> 541.22482 | AB15: ='A6b-Chin (LN&CoastalCU)'!AE22 -> 379.08414 | AC15: ='A6b-Chin (LN&CoastalCU)'!AL22 -> 269.77999 | AD15: =SUM(AA15:AC15) -> 1190.0889 | AF15: ='A6b-Chin (LN&CoastalCU)'!AM22 -> 6125.0434 | AH15: 2001 | AI15: =SUM(C15,Y15) -> 34275.837 | AK15: =SUM(N15,AA15) -> 13009.009 | AL15: =SUM(O15,AB15) -> 2633 | AM15: =SUM(P15,AC15) -> 2300 | AN15: =SUM(Q15,AD15) -> 17942.009 | AP15: =SUM(S15,AF15) -> 52217.963
B16: 2002 | C16: ='A6-Chin (NEW2)'!C23 -> 14360 | E16: ='A6-Chin (NEW2)'!D23 -> 11839 | F16: ='Bayesian SD Ests (10Feb26rev)'!D18 -> 2477 | H16: ='Bayesian SD Ests (10Feb26rev)'!F18 -> 2521 | I16: ='Bayesian SD Ests (10Feb26rev)'!G18 -> 998 | K16: ='A6-Chin (NEW2)'!L23 -> 17089 | L16: ='Bayesian SD Ests (10Feb26rev)'!V18 -> 2692 | N16: ='A6a-Chin (Upper&MidCU)'!AA23 -> 6179.5978 | O16: ='A6a-Chin (Upper&MidCU)'!AE23 -> 6203.9629 | P16: ='A6a-Chin (Upper&MidCU)'!AK23 -> 1249.1862 | Q16: =SUM(N16:P16) -> 13632.747 | S16: ='A6a-Chin (Upper&MidCU)'!AL23 -> 27992.747 | T16: =Q16/S16 -> 0.48700997 | U16: =(E16/(1-T16))*T16 -> 11239.421 | V16: =(H16/(1-T16))*T16 -> 2393.3255 | X16: 2002 | Y16: ='A6b-Chin (LN&CoastalCU)'!P23 -> 2064.7532 | AA16: ='A6b-Chin (LN&CoastalCU)'!AA23 -> 271.95085 | AB16: ='A6b-Chin (LN&CoastalCU)'!AE23 -> 892.03706 | AC16: ='A6b-Chin (LN&CoastalCU)'!AL23 -> 150.81383 | AD16: =SUM(AA16:AC16) -> 1314.8017 | AF16: ='A6b-Chin (LN&CoastalCU)'!AM23 -> 3379.6626 | AH16: 2002 | AI16: =SUM(C16,Y16) -> 16424.753 | AK16: =SUM(N16,AA16) -> 6451.5486 | AL16: =SUM(O16,AB16) -> 7096 | AM16: =SUM(P16,AC16) -> 1400 | AN16: =SUM(Q16,AD16) -> 14947.549 | AP16: =SUM(S16,AF16) -> 31372.409
B17: 2003 | C17: ='A6-Chin (NEW2)'!C24 -> 30740 | E17: ='A6-Chin (NEW2)'!D24 -> 25724 | F17: ='Bayesian SD Ests (10Feb26rev)'!D19 -> 5259 | H17: ='Bayesian SD Ests (10Feb26rev)'!F19 -> 5016 | I17: ='Bayesian SD Ests (10Feb26rev)'!G19 -> 1912 | K17: ='A6-Chin (NEW2)'!L24 -> 34354 | L17: ='Bayesian SD Ests (10Feb26rev)'!V19 -> 5642 | N17: ='A6a-Chin (Upper&MidCU)'!AA24 -> 7824.9266 | O17: ='A6a-Chin (Upper&MidCU)'!AE24 -> 6605.0676 | P17: ='A6a-Chin (Upper&MidCU)'!AK24 -> 2118.8423 | Q17: =SUM(N17:P17) -> 16548.836 | S17: ='A6a-Chin (Upper&MidCU)'!AL24 -> 47288.836 | T17: =Q17/S17 -> 0.34995229 | U17: =(E17/(1-T17))*T17 -> 13848.48 | V17: =(H17/(1-T17))*T17 -> 2700.3567 | X17: 2003 | Y17: ='A6b-Chin (LN&CoastalCU)'!P24 -> 2968.9386 | AA17: ='A6b-Chin (LN&CoastalCU)'!AA24 -> 255.09392 | AB17: ='A6b-Chin (LN&CoastalCU)'!AE24 -> 637.93235 | AC17: ='A6b-Chin (LN&CoastalCU)'!AL24 -> 181.15775 | AD17: =SUM(AA17:AC17) -> 1074.184 | AF17: ='A6b-Chin (LN&CoastalCU)'!AM24 -> 4043.2014 | AH17: 2003 | AI17: =SUM(C17,Y17) -> 33708.939 | AK17: =SUM(N17,AA17) -> 8080.0205 | AL17: =SUM(O17,AB17) -> 7243 | AM17: =SUM(P17,AC17) -> 2300 | AN17: =SUM(Q17,AD17) -> 17623.02 | AP17: =SUM(S17,AF17) -> 51332.038
B18: 2004 | C18: ='A6-Chin (NEW2)'!C25 -> 13736.6 | E18: ='A6-Chin (NEW2)'!D25 -> 11335.6 | F18: ='Bayesian SD Ests (10Feb26rev)'!D20 -> 2864 | H18: ='Bayesian SD Ests (10Feb26rev)'!F20 -> 2401 | I18: ='Bayesian SD Ests (10Feb26rev)'!G20 -> 864 | K18: ='A6-Chin (NEW2)'!L25 -> 16604 | L18: ='Bayesian SD Ests (10Feb26rev)'!V20 -> 3003 | N18: ='A6a-Chin (Upper&MidCU)'!AA25 -> 6678.758 | O18: ='A6a-Chin (Upper&MidCU)'!AE25 -> 8033.3278 | P18: ='A6a-Chin (Upper&MidCU)'!AK25 -> 534.41128 | Q18: =SUM(N18:P18) -> 15246.497 | S18: ='A6a-Chin (Upper&MidCU)'!AL25 -> 28983.097 | T18: =Q18/S18 -> 0.52604789 | U18: =(E18/(1-T18))*T18 -> 12581.584 | V18: =(H18/(1-T18))*T18 -> 2664.9127 | X18: 2004 | Y18: ='A6b-Chin (LN&CoastalCU)'!P25 -> 1841.9326 | AA18: ='A6b-Chin (LN&CoastalCU)'!AA25 -> 465.94581 | AB18: ='A6b-Chin (LN&CoastalCU)'!AE25 -> 1077.1842 | AC18: ='A6b-Chin (LN&CoastalCU)'!AL25 -> 63.588724 | AD18: =SUM(AA18:AC18) -> 1606.7187 | AF18: ='A6b-Chin (LN&CoastalCU)'!AM25 -> 3448.7576 | AH18: 2004 | AI18: =SUM(C18,Y18) -> 15578.533 | AK18: =SUM(N18,AA18) -> 7144.7038 | AL18: =SUM(O18,AB18) -> 9110.512 | AM18: =SUM(P18,AC18) -> 598 | AN18: =SUM(Q18,AD18) -> 16853.216 | AP18: =SUM(S18,AF18) -> 32431.855
B19: 2005 | C19: ='A6-Chin (NEW2)'!C26 -> 13109.8 | E19: ='A6-Chin (NEW2)'!D26 -> 10776.8 | F19: ='Bayesian SD Ests (10Feb26rev)'!D21 -> 2392 | H19: ='Bayesian SD Ests (10Feb26rev)'!F21 -> 2333 | I19: ='Bayesian SD Ests (10Feb26rev)'!G21 -> 804 | K19: ='A6-Chin (NEW2)'!L26 -> 16179 | L19: ='Bayesian SD Ests (10Feb26rev)'!V21 -> 2404 | N19: ='A6a-Chin (Upper&MidCU)'!AA26 -> 7276.1398 | O19: ='A6a-Chin (Upper&MidCU)'!AE26 -> 4178.8795 | P19: ='A6a-Chin (Upper&MidCU)'!AK26 -> 218.77131 | Q19: =SUM(N19:P19) -> 11673.791 | S19: ='A6a-Chin (Upper&MidCU)'!AL26 -> 24783.591 | T19: =Q19/S19 -> 0.47102903 | U19: =(E19/(1-T19))*T19 -> 9596.3407 | V19: =(H19/(1-T19))*T19 -> 2077.45 | X19: 2005 | Y19: ='A6b-Chin (LN&CoastalCU)'!P26 -> 2546.645 | AA19: ='A6b-Chin (LN&CoastalCU)'!AA26 -> 260.39687 | AB19: ='A6b-Chin (LN&CoastalCU)'!AE26 -> 811.7685 | AC19: ='A6b-Chin (LN&CoastalCU)'!AL26 -> 32.228688 | AD19: =SUM(AA19:AC19) -> 1104.3941 | AF19: ='A6b-Chin (LN&CoastalCU)'!AM26 -> 3651.1675 | AH19: 2005 | AI19: =SUM(C19,Y19) -> 15656.445 | AK19: =SUM(N19,AA19) -> 7536.5367 | AL19: =SUM(O19,AB19) -> 4990.648 | AM19: =SUM(P19,AC19) -> 251 | AN19: =SUM(Q19,AD19) -> 12778.185 | AP19: =SUM(S19,AF19) -> 28434.758
... B39: 2025 | C39: ='A6-Chin (NEW2)'!C46 -> 10359.973 | E39: ='A6-Chin (NEW2)'!D46 -> 8529.9727 | F39: ='Bayesian SD Ests (10Feb26rev)'!D41 -> 880 | H39: ='Bayesian SD Ests (10Feb26rev)'!F41 -> 1830 | I39: ='Bayesian SD Ests (10Feb26rev)'!G41 -> 811 | K39: ='A6-Chin (NEW2)'!L46 -> 12326 | L39: ='Bayesian SD Ests (10Feb26rev)'!V41 -> 1119 | N39: ='A6a-Chin (Upper&MidCU)'!AA46 -> 5199.8265 | O39: ='A6a-Chin (Upper&MidCU)'!AE46 -> 298.44376 | P39: ='A6a-Chin (Upper&MidCU)'!AK46 -> 741.62585 | Q39: =SUM(N39:P39) -> 6239.8961 | S39: ='A6a-Chin (Upper&MidCU)'!AL46 -> 16599.869 | T39: =Q39/S39 -> 0.37590033 | U39: =(E39/(1-T39))*T39 -> 5137.6721 | V39: =(H39/(1-T39))*T39 -> 1102.2239 | X39: 2025 | Y39: ='A6b-Chin (LN&CoastalCU)'!P46 -> 15029.316 | AA39: ='A6b-Chin (LN&CoastalCU)'!AA46 -> 95.41405 | AB39: ='A6b-Chin (LN&CoastalCU)'!AE46 -> 432.95534 | AC39: ='A6b-Chin (LN&CoastalCU)'!AL46 -> 727.56998 | AD39: =SUM(AA39:AC39) -> 1255.9394 | AF39: ='A6b-Chin (LN&CoastalCU)'!AM46 -> 16285.75 | AH39: 2025 | AI39: =SUM(C39,Y39) -> 25389.288 | AK39: =SUM(N39,AA39) -> 5295.2405 | AL39: =SUM(O39,AB39) -> 731.3991 | AM39: =SUM(P39,AC39) -> 1469.1958 | AN39: =SUM(Q39,AD39) -> 7495.8354 | AP39: =SUM(S39,AF39) -> 32885.619

Sheet A6-Chin (NEW2)
A1: Appendix A6. | C1: Annual estimates of escapement, catch and total stock size estimates for adult Chinook salmon returning to the Nass River, 1992 to present. | AN1: 0.25 | AO1: =AN1*V39 -> 5008.6873 | AX1: Total: ER | BS1: Canadian Commercial | BT1: Nisga'a Harvest | BU1: Gitanyow Harvest | BV1: Sport - Tidal | BW1: Sport - FW | BX1: Total Can. Catch | BY1: NEW TRTC | BZ1: Can HR% | CA1: Can Mar.HR% | CB1: Can IR HR% | CC1: US HR% | CD1: TOTAL HR% | CM1: Nass Chinook - Nisga'a Allocation Summary | DA1: Nisga'a%: | DB1: 0.21 | DD1: Max: | DE1: 12600
AX2: =AVERAGE(Z27:Z38) -> 5450.5857 | AY2: =AVERAGE(AC27:AC38) -> 1956.1727 | AZ2: =AVERAGE(AD27:AD38,Y27:Y38) -> 852.37111 | BA2: =AVERAGE(X27:X38) -> 138.66667 | BB2: =SUM(AX2:BA2) -> 8397.7961 | BC2: =AVERAGE(AK27:AK38) -> 1202.0833 | DD2: Esc: | DE2: 15000
C3: Upper & Middle Nass River | P3: Lower Nass R. & Coastal Nass Area | V3: Total Nass Area | AK3: Alaskan catchj | AL3: Total Runk | AX3: =AVERAGE(AX27:AX38) -> 0.20442026 | AY3: =AVERAGE(AY27:AY38) -> 0.069835168 | AZ3: =AVERAGE(AZ27:AZ38) -> 0.060743361 | BA3: =AVERAGE(BA27:BA38) -> 0.0048083772 | BB3: =AVERAGE(BB27:BB38) -> 0.33980717 | BC3: =AVERAGE(BC27:BC38) -> 0.045164018 | BD3: =BC3+AZ3+AY3 -> 0.17574255 | DD3: Min Esc G: | DE3: 10000
C4: Net Esc.a | G4: In-river Catch | L4: Run size to GWe | R4: In-river Catch | V4: Net Esc.g | X4: In-river Catch | AC4: Marine Catchh | AG4: Release Mortality | AJ4: Total Return to Canadai | AS4: Upper: | BG4: PSC - Table 1 | BK4: PSC - Table 1 | CF4: Original (11Dec25) | DA4: Max underage allowance | DB4: Underage Allowance
B5: Year | C5: Net Esc. totala | D5: Upper | E5: Middle | G5: UFN b | H5: Sportc | I5: Nisga'ad | J5: Total | M5: SF% | N5: Coastal Vis. Obs. | O5: Factor | P5: Net Esc.f | R5: Sportc | S5: Nisga'ad | T5: Total | U5: SF% | X5: UFN b | Y5: Sportc | Z5: Nisga'ad | AA5: Total | AC5: Comm. | AD5: Sport | AE5: Total | AG5: Comm | AH5: Sport | AI5: Nisga'a | AM5: DFO (23) | AN5: GH MR est. | AO5: Upper FN% | AP5: Rank (Lowest) | AR5: ER | AS5: Nisga'a | AT5: SF | AU5: Total | AX5: Nisga'a | AY5: Com. | AZ5: SF | BA5: Other | BB5: Total | BC5: Alaska | BG5: Upper-net | BH5: TRTC | BI5: Total Run | BK5: Upper-net | BL5: TRTC | BM5: Total Run | BO5: GH catch | BP5: Mez | BQ5: Kwin | CF5: TRTC | CG5: TR | CH5: TRTC Diff (new-old) | CI5: TR Diff (new-old) | CJ5: ESC old (11Dec25) | CK5: ESC Diff (new-old) | CM5: Year | CN5: TRTC | CO5: RAC | CP5: TAC | CQ5: Total Net Esc. | CR5: Min. Esc goal reached | CS5: Esc goal reached | CT5: Nisga'a share | CU5: Final Nisga'a share | CV5: Overharvest adjustment (4 d) | CW5: Overharvest adjustment (4 f) | CX5: Nisga'a harvest | CY5: Diff. | CZ5: MGT uncert. % | DC5: Signed off by JTC | DD5: Cum account | DE5: Table 9 new | DF5: Foregone | DH5: Coastal contribution | DK5: CF | DL5: SF | DS5: New Esc | DT5: Old Esc | DW5: New TRTC | DX5: Old TRTC | DY5: Diff | EG5: OTHER | EI5: Coastal/Upper | EJ5: Coastal/Total | EL5: Fishery officer | EM5: Escapement | EN5: Nisga'a | EO5: Other Can | EP5: Alaska | ET5: IN harvest rate | EW5: Other Canadian | FB5: Upper Nass | FC5: %Upper to lower | FE5: GW
B7: 1986 | C7: 36523.343 | G7: 166 | H7: 331 | I7: 939 | J7: 1436 | L7: =C7+J7 -> 37959.343 | P7: 2137.5 | R7: 0 | S7: 3038 | T7: =SUM(R7:S7) -> 3038 | V7: =SUM(P7,C7) -> 38660.843 | X7: 166 | Y7: 331 | Z7: 3977 | AA7: =SUM(X7:Z7) -> 4474 | AC7: 3259 | AD7: 1933 | AE7: =SUM(AC7:AD7) -> 5192 | AJ7: =SUM(V7,AA7,AE7,SUM(AG7:AI7)) -> 48326.843 | AK7: =ROUND(AJ7/(1-BC$53)-AJ7,-2) -> 2300 | AL7: =SUM(AJ7:AK7) -> 50626.843 | AN7: 9665.2108 | BS7: =AC7 -> 3259 | BT7: =Z7 -> 3977 | BU7: =X7 -> 166 | BV7: =AD7 -> 1933 | BW7: =Y7 -> 331 | BX7: =SUM(BS7:BW7) -> 9666 | BY7: =AJ7 -> 48326.843 | BZ7: =BX7/BY7 -> 0.20001307 | CA7: =SUM(BV7,BS7)/BX7 -> 0.53714049 | CB7: =SUM(BT7:BU7,BW7)/BX7 -> 0.46285951 | CC7: =AK7/(BX7+AK7) -> 0.19221127 | DH7: =P7/V7 -> 0.0552885 | EL7: =V7/1000 -> 38.660843 | EN7: =Z7/1000 -> 3.977 | EO7: =SUM(X7:Y7,AE7)/1000 -> 5.689 | EP7: =AK7/1000 -> 2.3 | ET7: =J7/L7 -> 0.037829949 | EW7: =BX7-BT7 -> 5689 | FE7: =ROUND(L7,-3) -> 38000
B8: 1987 | C8: 19539.879 | G8: 92 | H8: 184 | I8: 521 | J8: 797 | L8: =C8+J8 -> 20336.879 | P8: 1930.4061 | R8: 0 | S8: 1687 | T8: =SUM(R8:S8) -> 1687 | V8: =SUM(P8,C8) -> 21470.285 | X8: 92 | Y8: 184 | Z8: 2208 | AA8: =SUM(X8:Z8) -> 2484 | AC8: 1810 | AD8: 1074 | AE8: =SUM(AC8:AD8) -> 2884 | AJ8: =SUM(V8,AA8,AE8,SUM(AG8:AI8)) -> 26838.285 | AK8: =ROUND(AJ8/(1-BC$53)-AJ8,-2) -> 1300 | AL8: =SUM(AJ8:AK8) -> 28138.285 | AN8: 5367.5713 | BS8: =AC8 -> 1810 | BT8: =Z8 -> 2208 | BU8: =X8 -> 92 | BV8: =AD8 -> 1074 | BW8: =Y8 -> 184 | BX8: =SUM(BS8:BW8) -> 5368 | BY8: =AJ8 -> 26838.285 | BZ8: =BX8/BY8 -> 0.20001278 | CA8: =SUM(BV8,BS8)/BX8 -> 0.53725782 | CB8: =SUM(BT8:BU8,BW8)/BX8 -> 0.46274218 | CC8: =AK8/(BX8+AK8) -> 0.19496101 | DH8: =P8/V8 -> 0.089910592 | EL8: =V8/1000 -> 21.470285 | EN8: =Z8/1000 -> 2.208 | EO8: =SUM(X8:Y8,AE8)/1000 -> 3.16 | EP8: =AK8/1000 -> 1.3 | ET8: =J8/L8 -> 0.039189887 | EW8: =BX8-BT8 -> 3160 | FE8: =ROUND(L8,-3) -> 20000
B9: 1988 | C9: 15345.107 | G9: 72 | H9: 144 | I9: 409 | J9: 625 | L9: =C9+J9 -> 15970.107 | P9: 1503.185 | R9: 0 | S9: 1324 | T9: =SUM(R9:S9) -> 1324 | V9: =SUM(P9,C9) -> 16848.292 | X9: 72 | Y9: 144 | Z9: 1733 | AA9: =SUM(X9:Z9) -> 1949 | AC9: 1420 | AD9: 842 | AE9: =SUM(AC9:AD9) -> 2262 | AJ9: =SUM(V9,AA9,AE9,SUM(AG9:AI9)) -> 21059.292 | AK9: =ROUND(AJ9/(1-BC$53)-AJ9,-2) -> 1000 | AL9: =SUM(AJ9:AK9) -> 22059.292 | AN9: 4212.073 | BS9: =AC9 -> 1420 | BT9: =Z9 -> 1733 | BU9: =X9 -> 72 | BV9: =AD9 -> 842 | BW9: =Y9 -> 144 | BX9: =SUM(BS9:BW9) -> 4211 | BY9: =AJ9 -> 21059.292 | BZ9: =BX9/BY9 -> 0.19995924 | CA9: =SUM(BV9,BS9)/BX9 -> 0.53716457 | CB9: =SUM(BT9:BU9,BW9)/BX9 -> 0.46283543 | CC9: =AK9/(BX9+AK9) -> 0.19190175 | DH9: =P9/V9 -> 0.089218839 | EL9: =V9/1000 -> 16.848292 | EN9: =Z9/1000 -> 1.733 | EO9: =SUM(X9:Y9,AE9)/1000 -> 2.478 | EP9: =AK9/1000 -> 1 | ET9: =J9/L9 -> 0.039135618 | EW9: =BX9-BT9 -> 2478 | FE9: =ROUND(L9,-3) -> 16000
B10: 1989 | C10: 28133.121 | G10: 125 | H10: 250 | I10: 709 | J10: 1084 | L10: =C10+J10 -> 29217.121 | P10: 1068.0525 | R10: 0 | S10: 2295 | T10: =SUM(R10:S10) -> 2295 | V10: =SUM(P10,C10) -> 29201.173 | X10: 125 | Y10: 250 | Z10: 3004 | AA10: =SUM(X10:Z10) -> 3379 | AC10: 2461 | AD10: 1460 | AE10: =SUM(AC10:AD10) -> 3921 | AJ10: =SUM(V10,AA10,AE10,SUM(AG10:AI10)) -> 36501.173 | AK10: =ROUND(AJ10/(1-BC$53)-AJ10,-2) -> 1700 | AL10: =SUM(AJ10:AK10) -> 38201.173 | AN10: 7300.2934 | BS10: =AC10 -> 2461 | BT10: =Z10 -> 3004 | BU10: =X10 -> 125 | BV10: =AD10 -> 1460 | BW10: =Y10 -> 250 | BX10: =SUM(BS10:BW10) -> 7300 | BY10: =AJ10 -> 36501.173 | BZ10: =BX10/BY10 -> 0.19999357 | CA10: =SUM(BV10,BS10)/BX10 -> 0.53712329 | CB10: =SUM(BT10:BU10,BW10)/BX10 -> 0.46287671 | CC10: =AK10/(BX10+AK10) -> 0.18888889 | DH10: =P10/V10 -> 0.036575672 | EL10: =V10/1000 -> 29.201173 | EN10: =Z10/1000 -> 3.004 | EO10: =SUM(X10:Y10,AE10)/1000 -> 4.296 | EP10: =AK10/1000 -> 1.7 | ET10: =J10/L10 -> 0.037101534 | EW10: =BX10-BT10 -> 4296 | FE10: =ROUND(L10,-3) -> 29000
B11: 1990 | C11: 24051.46 | G11: 114 | H11: 227 | I11: 644 | J11: 985 | L11: =C11+J11 -> 25036.46 | P11: 2460 | R11: 0 | S11: 2083 | T11: =SUM(R11:S11) -> 2083 | V11: =SUM(P11,C11) -> 26511.46 | X11: 114 | Y11: 227 | Z11: 2727 | AA11: =SUM(X11:Z11) -> 3068 | AC11: 2235 | AD11: 1326 | AE11: =SUM(AC11:AD11) -> 3561 | AJ11: =SUM(V11,AA11,AE11,SUM(AG11:AI11)) -> 33140.46 | AK11: =ROUND(AJ11/(1-BC$53)-AJ11,-2) -> 1600 | AL11: =SUM(AJ11:AK11) -> 34740.46 | AN11: 6627.865 | BS11: =AC11 -> 2235 | BT11: =Z11 -> 2727 | BU11: =X11 -> 114 | BV11: =AD11 -> 1326 | BW11: =Y11 -> 227 | BX11: =SUM(BS11:BW11) -> 6629 | BY11: =AJ11 -> 33140.46 | BZ11: =BX11/BY11 -> 0.2000274 | CA11: =SUM(BV11,BS11)/BX11 -> 0.5371851 | CB11: =SUM(BT11:BU11,BW11)/BX11 -> 0.4628149 | CC11: =AK11/(BX11+AK11) -> 0.19443432 | DH11: =P11/V11 -> 0.092790061 | EL11: =V11/1000 -> 26.51146 | EN11: =Z11/1000 -> 2.727 | EO11: =SUM(X11:Y11,AE11)/1000 -> 3.902 | EP11: =AK11/1000 -> 1.6 | ET11: =J11/L11 -> 0.039342622 | EW11: =BX11-BT11 -> 3902 | FE11: =ROUND(L11,-3) -> 25000
B12: 1991 | C12: 6906.5654 | G12: 73 | H12: 146 | I12: 415 | J12: 634 | L12: =C12+J12 -> 7540.5654 | P12: 1019.1178 | R12: 0 | S12: 1341 | T12: =SUM(R12:S12) -> 1341 | V12: =SUM(P12,C12) -> 7925.6832 | X12: 73 | Y12: 146 | Z12: 1756 | AA12: =SUM(X12:Z12) -> 1975 | AC12: 1439 | AD12: 854 | AE12: =SUM(AC12:AD12) -> 2293 | AJ12: =SUM(V12,AA12,AE12,SUM(AG12:AI12)) -> 12193.683 | AK12: =ROUND(AJ12/(1-BC$53)-AJ12,-2) -> 600 | AL12: =SUM(AJ12:AK12) -> 12793.683 | AN12: 4267.6756 | BS12: =AC12 -> 1439 | BT12: =Z12 -> 1756 | BU12: =X12 -> 73 | BV12: =AD12 -> 854 | BW12: =Y12 -> 146 | BX12: =SUM(BS12:BW12) -> 4268 | BY12: =AJ12 -> 12193.683 | BZ12: =BX12/BY12 -> 0.35001729 | CA12: =SUM(BV12,BS12)/BX12 -> 0.53725398 | CB12: =SUM(BT12:BU12,BW12)/BX12 -> 0.46274602 | CC12: =AK12/(BX12+AK12) -> 0.1232539 | DH12: =P12/V12 -> 0.12858423 | EL12: =V12/1000 -> 7.9256832 | EN12: =Z12/1000 -> 1.756 | EO12: =SUM(X12:Y12,AE12)/1000 -> 2.512 | EP12: =AK12/1000 -> 0.6 | ET12: =J12/L12 -> 0.084078576 | EW12: =BX12-BT12 -> 2512 | FE12: =ROUND(L12,-3) -> 8000
B13: 1992 | C13: =L13-J13 -> 16808 | G13: ='[1]Data-Nisgaa & Other FN Catch'!BI5 -> 612 | H13: 1339 | I13: ='Data-Chin-Nisga''a'!N7 -> 1308.1728 | J13: =SUM(G13:I13) -> 3259.1728 | L13: ='Bayesian Sum (10Feb26)'!K8 -> 20067.173 | M13: =H13/L13 -> 0.066725892 | N13: ='Data-Coastal-Chin-Esc (new)'!J20 -> 605 | O13: =P13/N13 -> 2.3333278 | P13: ='Data-Coastal-Chin-Esc (new)'!AA20 -> 1411.6633 | R13: UNK | S13: ='Data-Chin-Nisga''a'!P7+'Data-Chin-Nisga''a'!Q7+'Data-Chin-Nisga''a'!O7 -> 5750.8272 | T13: =SUM(R13:S13) -> 5750.8272 | V13: =SUM(P13,C13) -> 18219.663 | X13: =G13 -> 612 | Y13: =SUM(H13,R13) -> 1339 | Z13: =SUM(I13,S13) -> 7059 | AA13: =SUM(X13:Z13) -> 9010 | AC13: ='A3.1b CF-tidal-Harvests (Chin)'!G7 -> 5464.5209 | AD13: 3207.1458 | AE13: =SUM(AC13:AD13) -> 8671.6667 | AJ13: =SUM(V13,AA13,AE13) -> 35901.33 | AK13: =ROUND(AJ13/(1-BC$53)-AJ13,-2) -> 1700 | AL13: =SUM(AJ13:AK13) -> 37601.33 | AN13: 20870 | AO13: =X13/AN13 -> 0.029324389 | AP13: =RANK(L13,L$13:L$46,1) -> 19 | AR13: =SUM(AE13,AA13,AK13)/AL13 -> 0.51545163 | AS13: =I13/$L13 -> 0.06518969 | AT13: =H13/$L13 -> 0.066725892 | AU13: =J13/$L13 -> 0.16241315 | AX13: =Z13/$AL13 -> 0.18773272 | AY13: =AC13/$AL13 -> 0.14532786 | AZ13: =SUM(Y13,AD13)/$AL13 -> 0.12090386 | BA13: =X13/AL13 -> 0.01627602 | BB13: =SUM(AA13,AE13)/AL13 -> 0.47024046 | BC13: =AK13/AL13 -> 0.045211167 | BD13: =SUM(AA13,AE13,AK13)/AL13 -> 0.51545163 | BG13: ='[1]Data-PSC CH Tables'!C7 -> 16808 | BH13: ='[1]Data-PSC CH Tables'!AG7 -> 35397.167 | BI13: ='[1]Data-PSC CH Tables'!AI7 -> 37197.167 | BK13: =BG13-C13 -> 0 | BL13: =BH13-AJ13 -> -504.1633 | BM13: =BI13-AL13 -> -404.1633 | BS13: =AC13 -> 5464.5209 | BT13: =Z13 -> 7059 | BU13: =X13 -> 612 | BV13: =AD13 -> 3207.1458 | BW13: =Y13 -> 1339 | BX13: =SUM(BS13:BW13) -> 17681.667 | BY13: =AJ13 -> 35901.33 | BZ13: =BX13/BY13 -> 0.49250729 | CA13: =SUM(BV13,BS13)/BX13 -> 0.49043265 | CB13: =SUM(BT13:BU13,BW13)/BX13 -> 0.50956735 | CC13: =AK13/(BX13+AK13) -> 0.087711755 | CF13: 35901.33 | CG13: 37701.33 | CH13: =CF13-AJ13 -> 0 | CI13: =CG13-AL13 -> 100 | CJ13: 18219.663 | CK13: =V13-CJ13 -> 0 | DH13: =P13/V13 -> 0.077480208 | DK13: =AA13+V13 -> 27229.663 | DN13: =($DK13*DK$50) -> 2608.8511 | DO13: =DN13/DK13 -> 0.095809158 | DP13: =($DK13*DL$50) -> 1047.681 | DQ13: =DP13/DK13 -> 0.038475722 | DS13: =V13 -> 18219.663 | DT13: 17715.5 | DU13: =DT13-DS13 -> -504.1633 | DW13: =AJ13 -> 35901.33 | DX13: 34686.667 | DY13: =DX13-DW13 -> -1214.6633 | EA13: 8671.6667 | EC13: =ROUND(EA13*EC$48,0) -> 5605 | ED13: =EA13-EC13 -> 3066.6667 | EE13: =SUM(EC13:ED13) -> 8671.6667 | EG13: =SUM(X13:Y13,AE13) -> 10622.667 | EI13: =$P13/B13 -> 0.70866631 | EJ13: =$P13/V13 -> 0.077480208 | EM13: =V13/1000 -> 18.219663 | EN13: =Z13/1000 -> 7.059 | EO13: =SUM(X13:Y13,AE13)/1000 -> 10.622667 | EP13: =AK13/1000 -> 1.7 | ET13: =J13/L13 -> 0.16241315 | EW13: =BX13-BT13 -> 10622.667 | EY13: =G13+H13 -> 1951 | EZ13: =EY13+R13 -> #VALUE! | FB13: =L13+SUM(S13,AE13,AK13)*FC13 -> 35130.041 | FC13: =L13/SUM(L13,P13) -> 0.93427655 | FE13: =ROUND(L13,-3) -> 20000
B14: 1993 | C14: =L14-J14 -> 24814 | G14: ='[1]Data-Nisgaa & Other FN Catch'!BI6 -> 600 | H14: 983 | I14: ='Data-Chin-Nisga''a'!N8 -> 1526.1184 | J14: =SUM(G14:I14) -> 3109.1184 | L14: ='Bayesian Sum (10Feb26)'!K9 -> 27923.118 | M14: =H14/L14 -> 0.035203804 | N14: ='Data-Coastal-Chin-Esc (new)'!J21 -> 782.82789 | O14: =P14/N14 -> 2.3333278 | P14: ='Data-Coastal-Chin-Esc (new)'!AA21 -> 1826.594 | R14: UNK | S14: ='Data-Chin-Nisga''a'!P8+'Data-Chin-Nisga''a'!Q8+'Data-Chin-Nisga''a'!O8 -> 4059.8816 | T14: =SUM(R14:S14) -> 4059.8816 | V14: =SUM(P14,C14) -> 26640.594 | X14: =G14 -> 600 | Y14: =SUM(H14,R14) -> 983 | Z14: =SUM(I14,S14) -> 5586 | AA14: =SUM(X14:Z14) -> 7169 | AC14: ='A3.1b CF-tidal-Harvests (Chin)'!G8 -> 7809.3391 | AD14: 4583.3275 | AE14: =SUM(AC14:AD14) -> 12392.667 | AJ14: =SUM(V14,AA14,AE14) -> 46202.261 | AK14: =ROUND(AJ14/(1-BC$53)-AJ14,-2) -> 2200 | AL14: =SUM(AJ14:AK14) -> 48402.261 | AN14: 21829.333 | AO14: =X14/AN14 -> 0.027485952 | AP14: =RANK(L14,L$13:L$46,1) -> 31 | AR14: =SUM(AE14,AA14,AK14)/AL14 -> 0.44960021 | AS14: =I14/L14 -> 0.054654298 | AT14: =H14/$L14 -> 0.035203804 | AU14: =J14/$L14 -> 0.11134567 | AX14: =Z14/$AL14 -> 0.11540783 | AY14: =AC14/$AL14 -> 0.16134245 | AZ14: =SUM(Y14,AD14)/$AL14 -> 0.1150014 | BA14: =X14/AL14 -> 0.012396115 | BB14: =SUM(AA14,AE14)/AL14 -> 0.40414779 | BC14: =AK14/AL14 -> 0.045452422 | BD14: =SUM(AA14,AE14,AK14)/AL14 -> 0.44960021 | BG14: ='[1]Data-PSC CH Tables'!C8 -> 24814 | BH14: ='[1]Data-PSC CH Tables'!AG8 -> 45414.425 | BI14: ='[1]Data-PSC CH Tables'!AI8 -> 47714.425 | BK14: =BG14-C14 -> 0 | BL14: =BH14-AJ14 -> -787.83581 | BM14: =BI14-AL14 -> -687.83581 | BS14: =AC14 -> 7809.3391 | BT14: =Z14 -> 5586 | BU14: =X14 -> 600 | BV14: =AD14 -> 4583.3275 | BW14: =Y14 -> 983 | BX14: =SUM(BS14:BW14) -> 19561.667 | BY14: =AJ14 -> 46202.261 | BZ14: =BX14/BY14 -> 0.42339198 | CA14: =SUM(BV14,BS14)/BX14 -> 0.63351793 | CB14: =SUM(BT14:BU14,BW14)/BX14 -> 0.36648207 | CC14: =AK14/(BX14+AK14) -> 0.1010952 | CF14: 46202.261 | CG14: 48502.261 | CH14: =CF14-AJ14 -> 0 | CI14: =CG14-AL14 -> 100 | CJ14: 26640.594 | CK14: =V14-CJ14 -> 0 | DH14: =P14/V14 -> 0.068564314 | DK14: =AA14+V14 -> 33809.594 | DN14: =(DK14*DK$50) -> 3239.2687 | DO14: =DN14/DK14 -> 0.095809158 | DP14: =($DK14*DL$50) -> 1300.8485 | DQ14: =DP14/DK14 -> 0.038475722 | DS14: =V14 -> 26640.594 | DT14: 25852.758 | DU14: =DT14-DS14 -> -787.83581 | DW14: =AJ14 -> 46202.261 | DX14: 49570.667 | DY14: =DX14-DW14 -> 3368.406 | EA14: 12392.667 | EC14: =ROUND(EA14*EC$48,0) -> 8009 | ED14: =EA14-EC14 -> 4383.6667 | EE14: =SUM(EC14:ED14) -> 12392.667 | EG14: =SUM(X14:Y14,AE14) -> 13975.667 | EI14: =P14/B14 -> 0.91650479 | EJ14: =$P14/V14 -> 0.068564314 | EM14: =V14/1000 -> 26.640594 | EN14: =Z14/1000 -> 5.586 | EO14: =SUM(X14:Y14,AE14)/1000 -> 13.975667 | EP14: =AK14/1000 -> 2.2 | ET14: =J14/L14 -> 0.11134567 | EW14: =BX14-BT14 -> 13975.667 | EY14: =G14+H14 -> 1583 | EZ14: =EY14+R14 -> #VALUE! | FB14: =L14+SUM(S14,AE14,AK14)*FC14 -> 45430.424 | FC14: =L14/SUM(L14,P14) -> 0.93860129 | FE14: =ROUND(L14,-3) -> 28000
B15: 1994 | C15: =L15-J15 -> 23639.335 | D15: =C15-E15 -> 19706.335 | E15: ='Bayesian Sum (10Feb26)'!H10 -> 3933 | G15: ='[1]Data-Nisgaa & Other FN Catch'!BI7 -> 120 | H15: 893 | I15: ='Data-Chin-Nisga''a'!N9 -> 2097.6648 | J15: =SUM(G15:I15) -> 3110.6648 | L15: ='Bayesian Sum (10Feb26)'!K10 -> 26750 | M15: =H15/L15 -> 0.033383178 | N15: ='Data-Coastal-Chin-Esc (new)'!J22 -> 2376.1408 | O15: =P15/N15 -> 2.3333278 | P15: ='Data-Coastal-Chin-Esc (new)'!AA22 -> 5544.3154 | R15: UNK | S15: ='Data-Chin-Nisga''a'!P9+'Data-Chin-Nisga''a'!Q9+'Data-Chin-Nisga''a'!O9 -> 4115.3352 | T15: =SUM(R15:S15) -> 4115.3352 | V15: =SUM(P15,C15) -> 29183.651 | X15: =G15 -> 120 | Y15: =SUM(H15,R15) -> 893 | Z15: =SUM(I15,S15) -> 6213 | AA15: =SUM(X15:Z15) -> 7226 | AC15: ='A3.1b CF-tidal-Harvests (Chin)'!G9 -> 6731.471 | AD15: 3950.7231 | AE15: =SUM(AC15:AD15) -> 10682.194 | AJ15: =SUM(V15,AA15,AE15) -> 47091.845 | AK15: =ROUND(AJ15/(1-BC$53)-AJ15,-2) -> 2300 | AL15: =SUM(AJ15:AK15) -> 49391.845 | AN15: ='[1]Data-FW Catch Rates - new'!CE9 -> 23205.075 | AO15: =X15/AN15 -> 0.0051712826 | AP15: =RANK(L15,L$13:L$46,1) -> 28 | AR15: =SUM(AE15,AA15,AK15)/AL15 -> 0.4091403 | AS15: =I15/L15 -> 0.078417375 | AT15: =H15/$L15 -> 0.033383178 | AU15: =J15/$L15 -> 0.11628653 | AX15: =Z15/$AL15 -> 0.12579 | AY15: =AC15/$AL15 -> 0.13628709 | AZ15: =SUM(Y15,AD15)/$AL15 -> 0.098067264 | BA15: =X15/AL15 -> 0.0024295509 | BB15: =SUM(AA15,AE15)/AL15 -> 0.36257391 | BC15: =AK15/AL15 -> 0.046566392 | BD15: =SUM(AA15,AE15,AK15)/AL15 -> 0.4091403 | BG15: ='[1]Data-PSC CH Tables'!C9 -> 21169 | BH15: ='[1]Data-PSC CH Tables'!AG9 -> 42779.776 | BI15: ='[1]Data-PSC CH Tables'!AI9 -> 44979.776 | BK15: =BG15-C15 -> -2470.3352 | BL15: =BH15-AJ15 -> -4312.0685 | BM15: =BI15-AL15 -> -4412.0685 | BS15: =AC15 -> 6731.471 | BT15: =Z15 -> 6213 | BU15: =X15 -> 120 | BV15: =AD15 -> 3950.7231 | BW15: =Y15 -> 893 | BX15: =SUM(BS15:BW15) -> 17908.194 | BY15: =AJ15 -> 47091.845 | BZ15: =BX15/BY15 -> 0.38028228 | CA15: =SUM(BV15,BS15)/BX15 -> 0.59649756 | CB15: =SUM(BT15:BU15,BW15)/BX15 -> 0.40350244 | CC15: =AK15/(BX15+AK15) -> 0.11381522 | CF15: 44621.509 | CG15: 46921.509 | CH15: =CF15-AJ15 -> -2470.3352 | CI15: =CG15-AL15 -> -2470.3352 | CJ15: 26713.315 | CK15: =V15-CJ15 -> 2470.3352 | DH15: =P15/V15 -> 0.18998019 | DK15: =AA15+V15 -> 36409.651 | DN15: =(DK15*DK$50) -> 3488.378 | DO15: =DN15/DK15 -> 0.095809158 | DP15: =($DK15*DL$50) -> 1400.8876 | DQ15: =DP15/DK15 -> 0.038475722 | DS15: =V15 -> 29183.651 | DT15: 24871.582 | DU15: =DT15-DS15 -> -4312.0685 | DW15: =AJ15 -> 47091.845 | DX15: 42728.776 | DY15: =DX15-DW15 -> -4363.0685 | EA15: 10682.194 | EC15: =ROUND(EA15*EC$48,0) -> 6904 | ED15: =EA15-EC15 -> 3778.194 | EE15: =SUM(EC15:ED15) -> 10682.194 | EG15: =SUM(X15:Y15,AE15) -> 11695.194 | EI15: =P15/B15 -> 2.7804992 | EJ15: =$P15/V15 -> 0.18998019 | EM15: =V15/1000 -> 29.183651 | EN15: =Z15/1000 -> 6.213 | EO15: =SUM(X15:Y15,AE15)/1000 -> 11.695194 | EP15: =AK15/1000 -> 2.3 | ET15: =J15/L15 -> 0.11628653 | EW15: =BX15-BT15 -> 11695.194 | EY15: =G15+H15 -> 1013 | EZ15: =EY15+R15 -> #VALUE! | FB15: =L15+SUM(S15,AE15,AK15)*FC15 -> 40912.211 | FC15: =L15/SUM(L15,P15) -> 0.82831915 | FE15: =ROUND(L15,-3) -> 27000
B16: 1995 | C16: =L16-J16 -> 9184.6097 | D16: =C16-E16 -> 7465.6097 | E16: ='Bayesian Sum (10Feb26)'!H11 -> 1719 | G16: ='[1]Data-Nisgaa & Other FN Catch'!BI8 -> 72 | H16: 695 | I16: ='Data-Chin-Nisga''a'!N10 -> 1812.3903 | J16: =SUM(G16:I16) -> 2579.3903 | L16: ='Bayesian Sum (10Feb26)'!K11 -> 11764 | M16: =H16/L16 -> 0.059078545 | N16: ='Data-Coastal-Chin-Esc (new)'!J23 -> 624.49855 | O16: =P16/N16 -> 2.3333278 | P16: ='Data-Coastal-Chin-Esc (new)'!AA23 -> 1457.1598 | R16: UNK | S16: ='Data-Chin-Nisga''a'!P10+'Data-Chin-Nisga''a'!Q10+'Data-Chin-Nisga''a'!O10 -> 4903.6097 | T16: =SUM(R16:S16) -> 4903.6097 | V16: =SUM(P16,C16) -> 10641.769 | X16: =G16 -> 72 | Y16: =SUM(H16,R16) -> 695 | Z16: =SUM(I16,S16) -> 6716 | AA16: =SUM(X16:Z16) -> 7483 | AC16: ='A3.1b CF-tidal-Harvests (Chin)'!G10 -> 3408.7592 | AD16: 2000.6123 | AE16: =SUM(AC16:AD16) -> 5409.3715 | AJ16: =SUM(V16,AA16,AE16) -> 23534.141 | AK16: =ROUND(AJ16/(1-BC$53)-AJ16,-2) -> 1100 | AL16: =SUM(AJ16:AK16) -> 24634.141 | AN16: ='[1]Data-FW Catch Rates - new'!CE10 -> 9910.0909 | AO16: =X16/AN16 -> 0.0072653218 | AP16: =RANK(L16,L$13:L$46,1) -> 5 | AR16: =SUM(AE16,AA16,AK16)/AL16 -> 0.56800728 | AS16: =I16/L16 -> 0.15406242 | AT16: =H16/$L16 -> 0.059078545 | AU16: =J16/$L16 -> 0.21926133 | AX16: =Z16/$AL16 -> 0.27262976 | AY16: =AC16/$AL16 -> 0.1383754 | AZ16: =SUM(Y16,AD16)/$AL16 -> 0.10942587 | BA16: =X16/AL16 -> 0.0029227729 | BB16: =SUM(AA16,AE16)/AL16 -> 0.52335381 | BC16: =AK16/AL16 -> 0.044653475 | BD16: =SUM(AA16,AE16,AK16)/AL16 -> 0.56800728 | BG16: ='[1]Data-PSC CH Tables'!C10 -> 7844 | BH16: ='[1]Data-PSC CH Tables'!AG10 -> 21709.486 | BI16: ='[1]Data-PSC CH Tables'!AI10 -> 22809.486 | BK16: =BG16-C16 -> -1340.6097 | BL16: =BH16-AJ16 -> -1824.6549 | BM16: =BI16-AL16 -> -1824.6549 | BS16: =AC16 -> 3408.7592 | BT16: =Z16 -> 6716 | BU16: =X16 -> 72 | BV16: =AD16 -> 2000.6123 | BW16: =Y16 -> 695 | BX16: =SUM(BS16:BW16) -> 12892.372 | BY16: =AJ16 -> 23534.141 | BZ16: =BX16/BY16 -> 0.54781568 | CA16: =SUM(BV16,BS16)/BX16 -> 0.41957925 | CB16: =SUM(BT16:BU16,BW16)/BX16 -> 0.58042075 | CC16: =AK16/(BX16+AK16) -> 0.078614265 | CF16: 22193.531 | CG16: 23293.531 | CH16: =CF16-AJ16 -> -1340.6097 | CI16: =CG16-AL16 -> -1340.6097 | CJ16: 9301.1598 | CK16: =V16-CJ16 -> 1340.6097 | DH16: =P16/V16 -> 0.13692834 | DK16: =AA16+V16 -> 18124.769 | DN16: =(DK16*DK$50) -> 1736.5189 | DO16: =DN16/DK16 -> 0.095809158 | DP16: =($DK16*DL$50) -> 697.36359 | DQ16: =DP16/DK16 -> 0.038475722 | DS16: =V16 -> 10641.769 | DT16: 8817.1145 | DU16: =DT16-DS16 -> -1824.6549 | DW16: =AJ16 -> 23534.141 | DX16: 21637.486 | DY16: =DX16-DW16 -> -1896.6549 | EA16: 5409.3715 | EC16: =ROUND(EA16*EC$48,0) -> 3496 | ED16: =EA16-EC16 -> 1913.3715 | EE16: =SUM(EC16:ED16) -> 5409.3715 | EG16: =SUM(X16:Y16,AE16) -> 6176.3715 | EI16: =P16/B16 -> 0.73040592 | EJ16: =$P16/V16 -> 0.13692834 | EM16: =V16/1000 -> 10.641769 | EN16: =Z16/1000 -> 6.716 | EO16: =SUM(X16:Y16,AE16)/1000 -> 6.1763715 | EP16: =AK16/1000 -> 1.1 | ET16: =J16/L16 -> 0.21926133 | EW16: =BX16-BT16 -> 6176.3715 | EY16: =G16+H16 -> 767 | EZ16: =EY16+R16 -> #VALUE! | FB16: =L16+SUM(S16,AE16,AK16)*FC16 -> 21919.108 | FC16: =L16/SUM(L16,P16) -> 0.88978578 | FE16: =ROUND(L16,-3) -> 12000
B17: 1996 | C17: =L17-J17 -> 21721.665 | D17: =C17-E17 -> 18211.665 | E17: ='Bayesian Sum (10Feb26)'!H12 -> 3510 | G17: ='[1]Data-Nisgaa & Other FN Catch'!BI9 -> 49 | H17: 477 | I17: ='Data-Chin-Nisga''a'!N11 -> 1834.3345 | J17: =SUM(G17:I17) -> 2360.3345 | L17: ='Bayesian Sum (10Feb26)'!K12 -> 24082 | M17: =H17/L17 -> 0.019807325 | N17: ='Data-Coastal-Chin-Esc (new)'!J24 -> 710.81136 | O17: =P17/N17 -> 2.3333278 | P17: ='Data-Coastal-Chin-Esc (new)'!AA24 -> 1658.5559 | R17: UNK | S17: ='Data-Chin-Nisga''a'!P11+'Data-Chin-Nisga''a'!Q11+'Data-Chin-Nisga''a'!O11 -> 5865.6655 | T17: =SUM(R17:S17) -> 5865.6655 | V17: =SUM(P17,C17) -> 23380.221 | X17: =G17 -> 49 | Y17: =SUM(H17,R17) -> 477 | Z17: =SUM(I17,S17) -> 7700 | AA17: =SUM(X17:Z17) -> 8226 | AC17: ='A3.1b CF-tidal-Harvests (Chin)'!G11 -> 6538.2283 | AD17: 3837.3083 | AE17: =SUM(AC17:AD17) -> 10375.537 | AJ17: =SUM(V17,AA17,AE17) -> 41981.758 | AK17: =ROUND(AJ17/(1-BC$53)-AJ17,-2) -> 2000 | AL17: =SUM(AJ17:AK17) -> 43981.758 | AN17: ='[1]Data-FW Catch Rates - new'!CE11 -> 21794.385 | AO17: =X17/AN17 -> 0.0022482855 | AP17: =RANK(L17,L$13:L$46,1) -> 26 | AR17: =SUM(AE17,AA17,AK17)/AL17 -> 0.46841094 | AS17: =I17/L17 -> 0.076170357 | AT17: =H17/$L17 -> 0.019807325 | AU17: =J17/$L17 -> 0.098012396 | AX17: =Z17/$AL17 -> 0.17507258 | AY17: =AC17/$AL17 -> 0.14865773 | AZ17: =SUM(Y17,AD17)/$AL17 -> 0.09809313 | BA17: =X17/AL17 -> 0.0011140983 | BB17: =SUM(AA17,AE17)/AL17 -> 0.42293754 | BC17: =AK17/AL17 -> 0.045473398 | BD17: =SUM(AA17,AE17,AK17)/AL17 -> 0.46841094 | BG17: ='[1]Data-PSC CH Tables'!C11 -> 21842 | BH17: ='[1]Data-PSC CH Tables'!AG11 -> 41551.147 | BI17: ='[1]Data-PSC CH Tables'!AI11 -> 43651.147 | BK17: =BG17-C17 -> 120.33453 | BL17: =BH17-AJ17 -> -430.61132 | BM17: =BI17-AL17 -> -330.61132 | BS17: =AC17 -> 6538.2283 | BT17: =Z17 -> 7700 | BU17: =X17 -> 49 | BV17: =AD17 -> 3837.3083 | BW17: =Y17 -> 477 | BX17: =SUM(BS17:BW17) -> 18601.537 | BY17: =AJ17 -> 41981.758 | BZ17: =BX17/BY17 -> 0.44308618 | CA17: =SUM(BV17,BS17)/BX17 -> 0.55777847 | CB17: =SUM(BT17:BU17,BW17)/BX17 -> 0.44222153 | CC17: =AK17/(BX17+AK17) -> 0.097080137 | CF17: 42102.093 | CG17: 44202.093 | CH17: =CF17-AJ17 -> 120.33453 | CI17: =CG17-AL17 -> 220.33453 | CJ17: 23500.556 | CK17: =V17-CJ17 -> -120.33453 | DH17: =P17/V17 -> 0.070938416 | DK17: =AA17+V17 -> 31606.221 | DN17: =(DK17*DK$50) -> 3028.1654 | DO17: =DN17/DK17 -> 0.095809158 | DP17: =($DK17*DL$50) -> 1216.0722 | DQ17: =DP17/DK17 -> 0.038475722 | DS17: =V17 -> 23380.221 | DT17: 22949.61 | DU17: =DT17-DS17 -> -430.61132 | DW17: =AJ17 -> 41981.758 | DX17: 41502.147 | DY17: =DX17-DW17 -> -479.61132 | EA17: 10375.537 | EC17: =ROUND(EA17*EC$48,0) -> 6706 | ED17: =EA17-EC17 -> 3669.5367 | EE17: =SUM(EC17:ED17) -> 10375.537 | EG17: =SUM(X17:Y17,AE17) -> 10901.537 | EI17: =P17/B17 -> 0.83093982 | EJ17: =$P17/V17 -> 0.070938416 | EM17: =V17/1000 -> 23.380221 | EN17: =Z17/1000 -> 7.7 | EO17: =SUM(X17:Y17,AE17)/1000 -> 10.901537 | EP17: =AK17/1000 -> 2 | ET17: =J17/L17 -> 0.098012396 | EW17: =BX17-BT17 -> 10901.537 | EY17: =G17+H17 -> 526 | EZ17: =EY17+R17 -> #VALUE! | FB17: =L17+SUM(S17,AE17,AK17)*FC17 -> 41147.856 | FC17: =L17/SUM(L17,P17) -> 0.93556643 | FE17: =ROUND(L17,-3) -> 24000
B18: 1997 | C18: =L18-J18 -> 21372.273 | D18: =C18-E18 -> 17879.273 | E18: ='Bayesian Sum (10Feb26)'!H13 -> 3493 | G18: ='[1]Data-Nisgaa & Other FN Catch'!BI10 -> 41 | H18: 203 | I18: ='Data-Chin-Nisga''a'!N12 -> 1876.7267 | J18: =SUM(G18:I18) -> 2120.7267 | L18: ='Bayesian Sum (10Feb26)'!K13 -> 23493 | M18: =H18/L18 -> 0.0086408717 | N18: ='Data-Coastal-Chin-Esc (new)'!J25 -> 688.34561 | O18: =P18/N18 -> 3.845355 | P18: ='Data-Coastal-Chin-Esc (new)'!AA25 -> 2646.9332 | R18: UNK | S18: ='Data-Chin-Nisga''a'!P12+'Data-Chin-Nisga''a'!Q12+'Data-Chin-Nisga''a'!O12 -> 4828.2733 | T18: =SUM(R18:S18) -> 4828.2733 | V18: =SUM(P18,C18) -> 24019.207 | X18: =G18 -> 41 | Y18: =SUM(H18,R18) -> 203 | Z18: =SUM(I18,S18) -> 6705 | AA18: =SUM(X18:Z18) -> 6949 | AC18: ='A3.1b CF-tidal-Harvests (Chin)'!G12 -> 5664.4139 | AD18: 3324.4636 | AE18: =SUM(AC18:AD18) -> 8988.8775 | AJ18: =SUM(V18,AA18,AE18) -> 39957.084 | AK18: =ROUND(AJ18/(1-BC$53)-AJ18,-2) -> 1900 | AL18: =SUM(AJ18:AK18) -> 41857.084 | AN18: ='[1]Data-FW Catch Rates - new'!CE12 -> 18702 | AO18: =X18/AN18 -> 0.0021922789 | AP18: =RANK(L18,L$13:L$46,1) -> 24 | AR18: =SUM(AE18,AA18,AK18)/AL18 -> 0.42616149 | AS18: =I18/L18 -> 0.079884506 | AT18: =H18/$L18 -> 0.0086408717 | AU18: =J18/$L18 -> 0.090270579 | AX18: =Z18/$AL18 -> 0.16018794 | AY18: =AC18/$AL18 -> 0.13532748 | AZ18: =SUM(Y18,AD18)/$AL18 -> 0.084273994 | BA18: =X18/AL18 -> 0.00097952356 | BB18: =SUM(AA18,AE18)/AL18 -> 0.38076894 | BC18: =AK18/AL18 -> 0.045392555 | BD18: =SUM(AA18,AE18,AK18)/AL18 -> 0.42616149 | BG18: ='[1]Data-PSC CH Tables'!C12 -> 18702 | BH18: ='[1]Data-PSC CH Tables'!AG12 -> 36275.172 | BI18: ='[1]Data-PSC CH Tables'!AI12 -> 38075.172 | BK18: =BG18-C18 -> -2670.2733 | BL18: =BH18-AJ18 -> -3681.9116 | BM18: =BI18-AL18 -> -3781.9116 | BS18: =AC18 -> 5664.4139 | BT18: =Z18 -> 6705 | BU18: =X18 -> 41 | BV18: =AD18 -> 3324.4636 | BW18: =Y18 -> 203 | BX18: =SUM(BS18:BW18) -> 15937.878 | BY18: =AJ18 -> 39957.084 | BZ18: =BX18/BY18 -> 0.39887489 | CA18: =SUM(BV18,BS18)/BX18 -> 0.56399464 | CB18: =SUM(BT18:BU18,BW18)/BX18 -> 0.43600536 | CC18: =AK18/(BX18+AK18) -> 0.10651491 | CF18: 37145.538 | CG18: 39045.538 | CH18: =CF18-AJ18 -> -2811.5465 | CI18: =CG18-AL18 -> -2811.5465 | CJ18: 21207.66 | CK18: =V18-CJ18 -> 2811.5465 | DH18: =P18/V18 -> 0.11020069 | DK18: =AA18+V18 -> 30968.207 | DN18: =(DK18*DK$50) -> 2967.0378 | DO18: =DN18/DK18 -> 0.095809158 | DP18: =($DK18*DL$50) -> 1191.5241 | DQ18: =DP18/DK18 -> 0.038475722 | DS18: =V18 -> 24019.207 | DT18: 19892.633 | DU18: =DT18-DS18 -> -4126.574 | DW18: =AJ18 -> 39957.084 | DX18: 35955.51 | DY18: =DX18-DW18 -> -4001.574 | EA18: 8988.8775 | EC18: =ROUND(EA18*EC$48,0) -> 5810 | ED18: =EA18-EC18 -> 3178.8775 | EE18: =SUM(EC18:ED18) -> 8988.8775 | EG18: =SUM(X18:Y18,AE18) -> 9232.8775 | EI18: =P18/B18 -> 1.3254548 | EJ18: =$P18/V18 -> 0.11020069 | EM18: =V18/1000 -> 24.019207 | EN18: =Z18/1000 -> 6.705 | EO18: =SUM(X18:Y18,AE18)/1000 -> 9.2328775 | EP18: =AK18/1000 -> 1.9 | ET18: =J18/L18 -> 0.090270579 | EW18: =BX18-BT18 -> 9232.8775 | EY18: =G18+H18 -> 244 | EZ18: =EY18+R18 -> #VALUE! | FB18: =L18+SUM(S18,AE18,AK18)*FC18 -> 37618.63 | FC18: =L18/SUM(L18,P18) -> 0.89873986 | FE18: =ROUND(L18,-3) -> 23000
B19: 1998 | C19: =L19-J19 -> 24908 | D19: =C19-E19 -> 20875 | E19: ='Bayesian Sum (10Feb26)'!H14 -> 4033 | G19: ='[1]Data-Nisgaa & Other FN Catch'!BI11 -> 345 | H19: 196 | I19: ='Data-Chin-Nisga''a'!N13 -> 1595 | J19: =SUM(G19:I19) -> 2136 | L19: ='Bayesian Sum (10Feb26)'!K14 -> 27044 | M19: =H19/L19 -> 0.0072474486 | N19: ='Data-Coastal-Chin-Esc (new)'!J26 -> 1101.8796 | O19: =P19/N19 -> 2.3333278 | P19: ='Data-Coastal-Chin-Esc (new)'!AA26 -> 2571.0462 | R19: UNK | S19: ='Data-Chin-Nisga''a'!P13+'Data-Chin-Nisga''a'!Q13+'Data-Chin-Nisga''a'!O13 -> 7470 | T19: =SUM(R19:S19) -> 7470 | V19: =SUM(P19,C19) -> 27479.046 | X19: =G19 -> 345 | Y19: =SUM(H19,R19) -> 196 | Z19: =SUM(I19,S19) -> 9065 | AA19: =SUM(X19:Z19) -> 9606 | AC19: ='A3.1b CF-tidal-Harvests (Chin)'!G13 -> 7191.3883 | AD19: 4220.6501 | AE19: =SUM(AC19:AD19) -> 11412.038 | AJ19: =SUM(V19,AA19,AE19) -> 48497.085 | AK19: =ROUND(AJ19/(1-BC$53)-AJ19,-2) -> 2300 | AL19: =SUM(AJ19:AK19) -> 50797.085 | AN19: ='[1]Data-FW Catch Rates - new'!CE13 -> 23511.998 | AO19: =X19/AN19 -> 0.01467336 | AP19: =RANK(L19,L$13:L$46,1) -> 29 | AR19: =SUM(AE19,AA19,AK19)/AL19 -> 0.45904285 | AS19: =I19/L19 -> 0.058977962 | AT19: =H19/$L19 -> 0.0072474486 | AU19: =J19/$L19 -> 0.078982399 | AX19: =Z19/$AL19 -> 0.17845512 | AY19: =AC19/$AL19 -> 0.14157089 | AZ19: =SUM(Y19,AD19)/$AL19 -> 0.086946921 | BA19: =X19/AL19 -> 0.0067917283 | BB19: =SUM(AA19,AE19)/AL19 -> 0.41376466 | BC19: =AK19/AL19 -> 0.045278189 | BD19: =SUM(AA19,AE19,AK19)/AL19 -> 0.45904285 | BG19: ='[1]Data-PSC CH Tables'!C13 -> 23212.998 | BH19: ='[1]Data-PSC CH Tables'!AG13 -> 45693.154 | BI19: ='[1]Data-PSC CH Tables'!AI13 -> 47993.154 | BK19: =BG19-C19 -> -1695.0023 | BL19: =BH19-AJ19 -> -2803.9309 | BM19: =BI19-AL19 -> -2803.9309 | BS19: =AC19 -> 7191.3883 | BT19: =Z19 -> 9065 | BU19: =X19 -> 345 | BV19: =AD19 -> 4220.6501 | BW19: =Y19 -> 196 | BX19: =SUM(BS19:BW19) -> 21018.038 | BY19: =AJ19 -> 48497.085 | BZ19: =BX19/BY19 -> 0.43338767 | CA19: =SUM(BV19,BS19)/BX19 -> 0.54296401 | CB19: =SUM(BT19:BU19,BW19)/BX19 -> 0.45703599 | CC19: =AK19/(BX19+AK19) -> 0.098636084 | CF19: 46802.082 | CG19: 49202.082 | CH19: =CF19-AJ19 -> -1695.0023 | CI19: =CG19-AL19 -> -1595.0023 | CJ19: 25784.044 | CK19: =V19-CJ19 -> 1695.0023 | DH19: =P19/V19 -> 0.093563882 | DK19: =AA19+V19 -> 37085.046 | DN19: =(DK19*DK$50) -> 3553.087 | DO19: =DN19/DK19 -> 0.095809158 | DP19: =($DK19*DL$50) -> 1426.8739 | DQ19: =DP19/DK19 -> 0.038475722 | DS19: =V19 -> 27479.046 | DT19: 24675.115 | DU19: =DT19-DS19 -> -2803.9309 | DW19: =AJ19 -> 48497.085 | DX19: 45648.154 | DY19: =DX19-DW19 -> -2848.9309 | EA19: 11412.038 | EC19: =ROUND(EA19*EC$48,0) -> 7376 | ED19: =EA19-EC19 -> 4036.0385 | EE19: =SUM(EC19:ED19) -> 11412.038 | EG19: =SUM(X19:Y19,AE19) -> 11953.038 | EI19: =P19/B19 -> 1.2868099 | EJ19: =$P19/V19 -> 0.093563882 | EM19: =V19/1000 -> 27.479046 | EN19: =Z19/1000 -> 9.065 | EO19: =SUM(X19:Y19,AE19)/1000 -> 11.953038 | EP19: =AK19/1000 -> 2.3 | ET19: =J19/L19 -> 0.078982399 | EW19: =BX19-BT19 -> 11953.038 | EY19: =G19+H19 -> 541 | EZ19: =EY19+R19 -> #VALUE! | FB19: =L19+SUM(S19,AE19,AK19)*FC19 -> 46387.108 | FC19: =L19/SUM(L19,P19) -> 0.91318446 | FE19: =ROUND(L19,-3) -> 27000
B20: 1999 | C20: =L20-J20 -> 13069 | D20: =C20-E20 -> 10844 | E20: ='Bayesian Sum (10Feb26)'!H15 -> 2225 | G20: ='[1]Data-Nisgaa & Other FN Catch'!BI12 -> 193 | H20: 82 | I20: ='Data-Chin-Nisga''a'!N14 -> 1608 | J20: =SUM(G20:I20) -> 1883 | L20: ='Bayesian Sum (10Feb26)'!K15 -> 14952 | M20: =H20/L20 -> 0.0054842162 | N20: ='Data-Coastal-Chin-Esc (new)'!J27 -> 740.06838 | O20: =P20/N20 -> 2.3333278 | P20: ='Data-Coastal-Chin-Esc (new)'!AA27 -> 1726.8221 | R20: UNK | S20: ='Data-Chin-Nisga''a'!P14+'Data-Chin-Nisga''a'!Q14+'Data-Chin-Nisga''a'!O14 -> 7309 | T20: =SUM(R20:S20) -> 7309 | V20: =SUM(P20,C20) -> 14795.822 | X20: =G20 -> 193 | Y20: =SUM(H20,R20) -> 82 | Z20: =SUM(I20,S20) -> 8917 | AA20: =SUM(X20:Z20) -> 9192 | AC20: ='A3.1b CF-tidal-Harvests (Chin)'!G14 -> 4561.9285 | AD20: 2677.4113 | AE20: =SUM(AC20:AD20) -> 7239.3398 | AJ20: =SUM(V20,AA20,AE20) -> 31227.162 | AK20: =ROUND(AJ20/(1-BC$53)-AJ20,-2) -> 1500 | AL20: =SUM(AJ20:AK20) -> 32727.162 | AN20: ='[1]Data-FW Catch Rates - new'!CE14 -> 11730.177 | AO20: =X20/AN20 -> 0.01645329 | AP20: =RANK(L20,L$13:L$46,1) -> 11 | AR20: =SUM(AE20,AA20,AK20)/AL20 -> 0.5479039 | AS20: =I20/L20 -> 0.10754414 | AT20: =H20/$L20 -> 0.0054842162 | AU20: =J20/$L20 -> 0.12593633 | AX20: =Z20/$AL20 -> 0.27246481 | AY20: =AC20/$AL20 -> 0.13939273 | AZ20: =SUM(Y20,AD20)/$AL20 -> 0.08431563 | BA20: =X20/AL20 -> 0.0058972422 | BB20: =SUM(AA20,AE20)/AL20 -> 0.50207042 | BC20: =AK20/AL20 -> 0.045833489 | BD20: =SUM(AA20,AE20,AK20)/AL20 -> 0.5479039 | BG20: ='[1]Data-PSC CH Tables'!C14 -> 11544 | BH20: ='[1]Data-PSC CH Tables'!AG14 -> 28957.359 | BI20: ='[1]Data-PSC CH Tables'!AI14 -> 30457.359 | BK20: =BG20-C20 -> -1525 | BL20: =BH20-AJ20 -> -2269.8028 | BM20: =BI20-AL20 -> -2269.8028 | BS20: =AC20 -> 4561.9285 | BT20: =Z20 -> 8917 | BU20: =X20 -> 193 | BV20: =AD20 -> 2677.4113 | BW20: =Y20 -> 82 | BX20: =SUM(BS20:BW20) -> 16431.34 | BY20: =AJ20 -> 31227.162 | BZ20: =BX20/BY20 -> 0.52618742 | CA20: =SUM(BV20,BS20)/BX20 -> 0.44058122 | CB20: =SUM(BT20:BU20,BW20)/BX20 -> 0.55941878 | CC20: =AK20/(BX20+AK20) -> 0.083652422 | CF20: 29702.162 | CG20: 31202.162 | CH20: =CF20-AJ20 -> -1525 | CI20: =CG20-AL20 -> -1525 | CJ20: 13270.822 | CK20: =V20-CJ20 -> 1525 | DH20: =P20/V20 -> 0.11671012 | DK20: =AA20+V20 -> 23987.822 | DN20: =(DK20*DK$50) -> 2298.253 | DO20: =DN20/DK20 -> 0.095809158 | DP20: =($DK20*DL$50) -> 922.94878 | DQ20: =DP20/DK20 -> 0.038475722 | DS20: =V20 -> 14795.822 | DT20: 12526.019 | DU20: =DT20-DS20 -> -2269.8028 | DW20: =AJ20 -> 31227.162 | DX20: 28957.359 | DY20: =DX20-DW20 -> -2269.8028 | EA20: 7239.3398 | EC20: =ROUND(EA20*EC$48,0) -> 4679 | ED20: =EA20-EC20 -> 2560.3398 | EE20: =SUM(EC20:ED20) -> 7239.3398 | EG20: =SUM(X20:Y20,AE20) -> 7514.3398 | EI20: =P20/B20 -> 0.86384297 | EJ20: =$P20/V20 -> 0.11671012 | EM20: =V20/1000 -> 14.795822 | EN20: =Z20/1000 -> 8.917 | EO20: =SUM(X20:Y20,AE20)/1000 -> 7.5143398 | EP20: =AK20/1000 -> 1.5 | ET20: =J20/L20 -> 0.12593633 | EW20: =BX20-BT20 -> 7514.3398 | EY20: =G20+H20 -> 275 | EZ20: =EY20+R20 -> #VALUE! | FB20: =L20+SUM(S20,AE20,AK20)*FC20 -> 29338.794 | FC20: =L20/SUM(L20,P20) -> 0.89646618 | FE20: =ROUND(L20,-3) -> 15000
B21: 2000 | C21: =L21-J21 -> 18085 | D21: =C21-E21 -> 14915 | E21: ='Bayesian Sum (10Feb26)'!H16 -> 3170 | G21: ='[1]Data-Nisgaa & Other FN Catch'!BI13 -> 49 | H21: ='[1]Data-SF-FW'!U4 -> 1023 | I21: ='Data-Chin-Nisga''a'!N15 -> 2498 | J21: =SUM(G21:I21) -> 3570 | L21: ='Bayesian Sum (10Feb26)'!K16 -> 21655 | M21: =H21/L21 -> 0.047240822 | N21: ='Data-Coastal-Chin-Esc (new)'!J28 -> 822.75788 | O21: =P21/N21 -> 2.3333278 | P21: ='Data-Coastal-Chin-Esc (new)'!AA28 -> 1919.7638 | R21: =SUM('[1]Data-SF-FW'!C4:H4) -> 214.4673 | S21: ='Data-Chin-Nisga''a'!P15+'Data-Chin-Nisga''a'!Q15+'Data-Chin-Nisga''a'!O15 -> 6828 | T21: =SUM(R21:S21) -> 7042.4673 | U21: =R21/SUM(T21,P21) -> 0.023930124 | V21: =SUM(P21,C21) -> 20004.764 | X21: =G21 -> 49 | Y21: =SUM(H21,R21) -> 1237.4673 | Z21: =SUM(I21,S21) -> 9326 | AA21: =SUM(X21:Z21) -> 10612.467 | AC21: ='A3.1b CF-tidal-Harvests (Chin)'!G15 -> 1826 | AD21: ='A3.1b CF-tidal-Harvests (Chin)'!L15 -> 986 | AE21: =SUM(AC21:AD21) -> 2812 | AJ21: =SUM(V21,AA21,AE21) -> 33429.231 | AK21: =ROUND(AJ21/(1-BC$53)-AJ21,-2) -> 1600 | AL21: =SUM(AJ21:AK21) -> 35029.231 | AN21: ='[1]Data-FW Catch Rates - new'!CE15 -> 18488.665 | AO21: =X21/AN21 -> 0.0026502724 | AP21: =RANK(L21,L$13:L$46,1) -> 22 | AR21: =SUM(AE21,AA21,AK21)/AL21 -> 0.42891228 | AS21: =I21/L21 -> 0.11535442 | AT21: =H21/$L21 -> 0.047240822 | AU21: =J21/$L21 -> 0.164858 | AX21: =Z21/$AL21 -> 0.26623479 | AY21: =AC21/$AL21 -> 0.052127893 | AZ21: =SUM(Y21,AD21)/$AL21 -> 0.063474625 | BA21: =X21/AL21 -> 0.0013988317 | BB21: =SUM(AA21,AE21)/AL21 -> 0.38323614 | BC21: =AK21/AL21 -> 0.045676138 | BD21: =SUM(AA21,AE21,AK21)/AL21 -> 0.42891228 | BG21: ='[1]Data-PSC CH Tables'!C15 -> 18046.704 | BH21: ='[1]Data-PSC CH Tables'!AG15 -> 32772.911 | BI21: ='[1]Data-PSC CH Tables'!AI15 -> 34472.911 | BK21: =BG21-C21 -> -38.296009 | BL21: =BH21-AJ21 -> -656.31972 | BM21: =BI21-AL21 -> -556.31972 | BS21: =AC21 -> 1826 | BT21: =Z21 -> 9326 | BU21: =X21 -> 49 | BV21: =AD21 -> 986 | BW21: =Y21 -> 1237.4673 | BX21: =SUM(BS21:BW21) -> 13424.467 | BY21: =AJ21 -> 33429.231 | BZ21: =BX21/BY21 -> 0.4015787 | CA21: =SUM(BV21,BS21)/BX21 -> 0.20946827 | CB21: =SUM(BT21:BU21,BW21)/BX21 -> 0.79053173 | CC21: =AK21/(BX21+AK21) -> 0.10649296 | CF21: 33390.935 | CG21: 35090.935 | CH21: =CF21-AJ21 -> -38.296009 | CI21: =CG21-AL21 -> 61.703991 | CJ21: 19966.468 | CK21: =V21-CJ21 -> 38.296009 | CM21: =B21 -> 2000 | CN21: =AJ21 -> 33429.231 | CO21: =IF((CN21-DE$2-CT21)>0, (CN21-DE$2-CT21),0) -> 11409.093 | CP21: =CO21+CT21 -> 18429.231 | CQ21: =V21 -> 20004.764 | CR21: =IF(ROUND(CQ21,-3)>=DE$3,"Y","N") -> Y | CS21: =IF(CQ21>DE$2,"Y","N") -> Y | CT21: =IF(CN21*DB$1>12600,12600,CN21*DB$1) -> 7020.1385 | CU21: =IF(CS21="N",(BX21-BT21)+CT21,CT21) -> 7020.1385 | CX21: =BT21 -> 9326 | CY21: =CX21-CU21 -> 2305.8615 | CZ21: 1 | DA21: =IF(CZ21=100%,CY21,CZ21*CT21*-1) -> 2305.8615 | DB21: =IF(CX21>CT21,CY21,(IF(CY21*-1>(CT21*CZ21),CT21*CZ21*-1,CY21))) -> 2305.8615 | DC21: 2391 | DD21: =DC21+DD20 -> 2391 | DE21: =DB21 -> 2305.8615 | DF21: =IF($DB21>0,$DB21,$DB21*-1) -> 2305.8615 | DH21: =P21/V21 -> 0.095965333 | DK21: =AC21/AJ21 -> 0.054622854 | DL21: =AD21/AJ21 -> 0.029495144 | DS21: =V21 -> 20004.764 | DT21: 19348.444 | DU21: =DT21-DS21 -> -656.31972 | DW21: =AJ21 -> 33429.231 | DX21: 32617.444 | DY21: =DX21-DW21 -> -811.78703 | EC21: =AC21/$AE21 -> 0.64935989 | ED21: =AD21/$AE21 -> 0.35064011 | EG21: =SUM(X21:Y21,AE21) -> 4098.4673 | EI21: =P21/B21 -> 0.95988191 | EJ21: =$P21/V21 -> 0.095965333 | EM21: =V21/1000 -> 20.004764 | EN21: =Z21/1000 -> 9.326 | EO21: =SUM(X21:Y21,AE21)/1000 -> 4.0984673 | EP21: =AK21/1000 -> 1.6 | ET21: =J21/L21 -> 0.164858 | EW21: =BX21-BT21 -> 4098.4673 | EY21: =G21+H21 -> 1072 | EZ21: =EY21+R21 -> 1286.4673 | FB21: =L21+SUM(S21,AE21,AK21)*FC21 -> 31979.693 | FC21: =L21/SUM(L21,P21) -> 0.918567 | FE21: =ROUND(L21,-3) -> 22000
